Workbook
Name NativeTimeline_Date: #N/A
Name NativeTimeline_Date1: #N/A
Name NativeTimeline_Date2: #N/A
Name Slicer_Category: #N/A
Name Slicer_Category1: #N/A
Name Slicer_Product: #N/A
Name Slicer_Profit: #N/A
Name Slicer_Region: #N/A
Name Slicer_Region1: #N/A
Name Slicer_Region2: #N/A
Name Slicer_Revenue: #N/A

Sheet Sheet6
A3: Products | B3: Sum of Revenue
A4: Headphones | B4: 22160
A5: Grand Total | B5: 22160

Sheet Sheet7
A3: Row Labels | B3: Sum of Revenue | C3: Sum of Profit | D3: Sum of Profit Margin %
A4: Headphones | B4: 92783 | C4: -1694 | D4: -0.018257655
A5: Laptop | B5: 100036 | C5: -70910 | D5: -0.70884482
A6: Monitor | B6: 100690 | C6: -25944 | D6: -0.25766213
A7: Printer | B7: 49991 | C7: -25089 | D7: -0.50187034
A8: Smartphone | B8: 37743 | C8: -36649 | D8: -0.97101449
A9: Tablet | B9: 60019 | C9: -80448 | D9: -1.3403755
A10: Grand Total | B10: 441262 | C10: -240734 | D10: -0.54555797

Sheet Sales_All
A1: OrderID | B1: Date | C1: Region | D1: CustomerID | E1: Product | F1: Quantity | G1: UnitPrice | H1: Category | I1: UnitCost | J1: Discount | K1: Revenue | L1: Discounted Revenue | M1: Profit | N1: Nested IFs | O1: Match & Index | P1: Dynamic Range | R1: DeliveryDays
A2: Q1-026 | B2: 45660.18 | C2: North | D2: 1009 | E2: Headphones | F2: 1 | G2: 1841 | H2: =_xlfn.XLOOKUP(E2, Products!A:A, Products!B:B, "Not Found") -> Accessories | I2: =_xlfn.XLOOKUP(E2, Products!A:A, Products!D:D, 0) -> 323 | J2: =_xlfn.XLOOKUP(E2, Products!A:A, Products!E:E, 0) -> 0.1 | K2: =SUM(F2*G2) -> 1841 | L2: =SUM(K2*(1-J2)) -> 1656.9 | M2: =ABS(K2- (Append1[[#This Row],[Quantity]]*Append1[[#This Row],[UnitCost]]) - Finance!B2) -> 24122 | N2: =IF(K2>50000, "VIP", IF(K2>=20000, "Regular", "Low Value")) -> Low Value | O2: =INDEX(E2:E91, MATCH(H2, H2:H91, 0)) -> Headphones | P2: {=OFFSET($H$2,0,0,COUNTA($H:$H)-1,2)} -> Accessories | Q2: 323 | R2: =_xlfn.XLOOKUP(A2, Operations!A:A, Operations!B:B, "") -> 3
A3: Q1-023 | B3: 45662.649 | C3: West | D3: 1006 | E3: Laptop | F3: 3 | G3: 1752 | H3: =_xlfn.XLOOKUP(E3, Products!A:A, Products!B:B, "Not Found") -> Electronics | I3: =_xlfn.XLOOKUP(E3, Products!A:A, Products!D:D, 0) -> 469 | J3: =_xlfn.XLOOKUP(E3, Products!A:A, Products!E:E, 0) -> 0.22 | K3: =SUM(F3*G3) -> 5256 | L3: =SUM(K3*(1-J3)) -> 4099.68 | M3: =SUM(K3- (Append1[[#This Row],[Quantity]]*Append1[[#This Row],[UnitCost]]) - Finance!B2) -> -21791 | N3: =IF(K3>50000, "VIP", IF(K3>=20000, "Regular", "Low Value")) -> Low Value | O3: =INDEX(E3:E92, MATCH(H3, H3:H92, 0)) -> Laptop | P3: Electronics | Q3: 469 | R3: =_xlfn.XLOOKUP(A3, Operations!A:A, Operations!B:B, "") -> 3
A4: Q1-012 | B4: 45662.79 | C4: South | D4: 1016 | E4: Laptop | F4: 3 | G4: 1692 | H4: =_xlfn.XLOOKUP(E4, Products!A:A, Products!B:B, "Not Found") -> Electronics | I4: =_xlfn.XLOOKUP(E4, Products!A:A, Products!D:D, 0) -> 469 | J4: =_xlfn.XLOOKUP(E4, Products!A:A, Products!E:E, 0) -> 0.22 | K4: =SUM(F4*G4) -> 5076 | L4: =SUM(K4*(1-J4)) -> 3959.28 | M4: =SUM(K4- (Append1[[#This Row],[Quantity]]*Append1[[#This Row],[UnitCost]]) - Finance!B2) -> -21971 | N4: =IF(K4>50000, "VIP", IF(K4>=20000, "Regular", "Low Value")) -> Low Value | O4: =INDEX(E4:E93, MATCH(H4, H4:H93, 0)) -> Laptop | P4: Electronics | Q4: 469 | R4: =_xlfn.XLOOKUP(A4, Operations!A:A, Operations!B:B, "") -> 8
A5: Q1-005 | B5: 45663.686 | C5: North | D5: 1012 | E5: Laptop | F5: 2 | G5: 709 | H5: =_xlfn.XLOOKUP(E5, Products!A:A, Products!B:B, "Not Found") -> Electronics | I5: =_xlfn.XLOOKUP(E5, Products!A:A, Products!D:D, 0) -> 469 | J5: =_xlfn.XLOOKUP(E5, Products!A:A, Products!E:E, 0) -> 0.22 | K5: =SUM(F5*G5) -> 1418 | L5: =SUM(K5*(1-J5)) -> 1106.04 | M5: =SUM(K5- (Append1[[#This Row],[Quantity]]*Append1[[#This Row],[UnitCost]]) - Finance!B2) -> -25160 | N5: =IF(K5>50000, "VIP", IF(K5>=20000, "Regular", "Low Value")) -> Low Value | O5: =INDEX(E5:E94, MATCH(H5, H5:H94, 0)) -> Laptop | P5: Electronics | Q5: 469 | R5: =_xlfn.XLOOKUP(A5, Operations!A:A, Operations!B:B, "") -> 5
A6: Q1-030 | B6: 45666.628 | C6: East | D6: 1016 | E6: Monitor | F6: 5 | G6: 1119 | H6: =_xlfn.XLOOKUP(E6, Products!A:A, Products!B:B, "Not Found") -> Electronics | I6: =_xlfn.XLOOKUP(E6, Products!A:A, Products!D:D, 0) -> 463 | J6: =_xlfn.XLOOKUP(E6, Products!A:A, Products!E:E, 0) -> 0.23 | K6: =SUM(F6*G6) -> 5595 | L6: =SUM(K6*(1-J6)) -> 4308.15 | M6: =SUM(K6- (Append1[[#This Row],[Quantity]]*Append1[[#This Row],[UnitCost]]) - Finance!B2) -> -22360 | N6: =IF(K6>50000, "VIP", IF(K6>=20000, "Regular", "Low Value")) -> Low Value | O6: =INDEX(E6:E95, MATCH(H6, H6:H95, 0)) -> Monitor | P6: Electronics | Q6: 463 | R6: =_xlfn.XLOOKUP(A6, Operations!A:A, Operations!B:B, "") -> 2
A7: Q1-009 | B7: 45671.497 | C7: South | D7: 1020 | E7: Printer | F7: 1 | G7: 1220 | H7: =_xlfn.XLOOKUP(E7, Products!A:A, Products!B:B, "Not Found") -> Office | I7: =_xlfn.XLOOKUP(E7, Products!A:A, Products!D:D, 0) -> 136 | J7: =_xlfn.XLOOKUP(E7, Products!A:A, Products!E:E, 0) -> 0.1 | K7: =SUM(F7*G7) -> 1220 | L7: =SUM(K7*(1-J7)) -> 1098 | M7: =SUM(K7- (Append1[[#This Row],[Quantity]]*Append1[[#This Row],[UnitCost]]) - Finance!B2) -> -24556 | N7: =IF(K7>50000, "VIP", IF(K7>=20000, "Regular", "Low Value")) -> Low Value | O7: =INDEX(E7:E96, MATCH(H7, H7:H96, 0)) -> Printer | P7: Office | Q7: 136 | R7: =_xlfn.XLOOKUP(A7, Operations!A:A, Operations!B:B, "") -> 2
A8: Q1-015 | B8: 45672.073 | C8: South | D8: 1016 | E8: Monitor | F8: 3 | G8: 1355 | H8: =_xlfn.XLOOKUP(E8, Products!A:A, Products!B:B, "Not Found") -> Electronics | I8: =_xlfn.XLOOKUP(E8, Products!A:A, Products!D:D, 0) -> 463 | J8: =_xlfn.XLOOKUP(E8, Products!A:A, Products!E:E, 0) -> 0.23 | K8: =SUM(F8*G8) -> 4065 | L8: =SUM(K8*(1-J8)) -> 3130.05 | M8: =SUM(K8- (Append1[[#This Row],[Quantity]]*Append1[[#This Row],[UnitCost]]) - Finance!B2) -> -22964 | N8: =IF(K8>50000, "VIP", IF(K8>=20000, "Regular", "Low Value")) -> Low Value | O8: =INDEX(E8:E97, MATCH(H8, H8:H97, 0)) -> Monitor | P8: Electronics | Q8: 463 | R8: =_xlfn.XLOOKUP(A8, Operations!A:A, Operations!B:B, "") -> 4
A9: Q1-011 | B9: 45684.929 | C9: West | D9: 1019 | E9: Laptop | F9: 9 | G9: 417 | H9: =_xlfn.XLOOKUP(E9, Products!A:A, Products!B:B, "Not Found") -> Electronics | I9: =_xlfn.XLOOKUP(E9, Products!A:A, Products!D:D, 0) -> 469 | J9: =_xlfn.XLOOKUP(E9, Products!A:A, Products!E:E, 0) -> 0.22 | K9: =SUM(F9*G9) -> 3753 | L9: =SUM(K9*(1-J9)) -> 2927.34 | M9: =SUM(K9- (Append1[[#This Row],[Quantity]]*Append1[[#This Row],[UnitCost]]) - Finance!B2) -> -26108 | N9: =IF(K9>50000, "VIP", IF(K9>=20000, "Regular", "Low Value")) -> Low Value | O9: =INDEX(E9:E98, MATCH(H9, H9:H98, 0)) -> Laptop | P9: Electronics | Q9: 469 | R9: =_xlfn.XLOOKUP(A9, Operations!A:A, Operations!B:B, "") -> 8
A10: Q1-028 | B10: 45685.124 | C10: West | D10: 1003 | E10: Monitor | F10: 6 | G10: 1011 | H10: =_xlfn.XLOOKUP(E10, Products!A:A, Products!B:B, "Not Found") -> Electronics | I10: =_xlfn.XLOOKUP(E10, Products!A:A, Products!D:D, 0) -> 463 | J10: =_xlfn.XLOOKUP(E10, Products!A:A, Products!E:E, 0) -> 0.23 | K10: =SUM(F10*G10) -> 6066 | L10: =SUM(K10*(1-J10)) -> 4670.82 | M10: =SUM(K10- (Append1[[#This Row],[Quantity]]*Append1[[#This Row],[UnitCost]]) - Finance!B30) -> 3288 | N10: =IF(K10>50000, "VIP", IF(K10>=20000, "Regular", "Low Value")) -> Low Value | O10: =INDEX(E10:E99, MATCH(H10, H10:H99, 0)) -> Monitor | P10: Electronics | Q10: 463 | R10: =_xlfn.XLOOKUP(A10, Operations!A:A, Operations!B:B, "") -> 2
A11: Q1-017 | B11: 45688.214 | C11: North | D11: 1008 | E11: Smartphone | F11: 3 | G11: 605 | H11: =_xlfn.XLOOKUP(E11, Products!A:A, Products!B:B, "Not Found") -> Electronics | I11: =_xlfn.XLOOKUP(E11, Products!A:A, Products!D:D, 0) -> 97 | J11: =_xlfn.XLOOKUP(E11, Products!A:A, Products!E:E, 0) -> 0.08 | K11: =SUM(F11*G11) -> 1815 | L11: =SUM(K11*(1-J11)) -> 1669.8 | M11: =SUM(K11- (Append1[[#This Row],[Quantity]]*Append1[[#This Row],[UnitCost]]) - Finance!B2) -> -24116 | N11: =IF(K11>50000, "VIP", IF(K11>=20000, "Regular", "Low Value")) -> Low Value | O11: =INDEX(E11:E100, MATCH(H11, H11:H100, 0)) -> Smartphone | P11: Electronics | Q11: 97 | R11: =_xlfn.XLOOKUP(A11, Operations!A:A, Operations!B:B, "") -> 6
A12: Q1-013 | B12: 45693.46 | C12: East | D12: 1001 | E12: Printer | F12: 4 | G12: 1853 | H12: =_xlfn.XLOOKUP(E12, Products!A:A, Products!B:B, "Not Found") -> Office | I12: =_xlfn.XLOOKUP(E12, Products!A:A, Products!D:D, 0) -> 136 | J12: =_xlfn.XLOOKUP(E12, Products!A:A, Products!E:E, 0) -> 0.1 | K12: =SUM(F12*G12) -> 7412 | L12: =SUM(K12*(1-J12)) -> 6670.8 | M12: =SUM(K12- (Append1[[#This Row],[Quantity]]*Append1[[#This Row],[UnitCost]]) - Finance!B3) -> -36452 | N12: =IF(K12>50000, "VIP", IF(K12>=20000, "Regular", "Low Value")) -> Low Value | O12: =INDEX(E12:E101, MATCH(H12, H12:H101, 0)) -> Printer | P12: Office | Q12: 136 | R12: =_xlfn.XLOOKUP(A12, Operations!A:A, Operations!B:B, "") -> 1
A13: Q1-019 | B13: 45696.452 | C13: North | D13: 1010 | E13: Headphones | F13: 1 | G13: 1621 | H13: =_xlfn.XLOOKUP(E13, Products!A:A, Products!B:B, "Not Found") -> Accessories | I13: =_xlfn.XLOOKUP(E13, Products!A:A, Products!D:D, 0) -> 323 | J13: =_xlfn.XLOOKUP(E13, Products!A:A, Products!E:E, 0) -> 0.1 | K13: =SUM(F13*G13) -> 1621 | L13: =SUM(K13*(1-J13)) -> 1458.9 | M13: =SUM(K13- (Append1[[#This Row],[Quantity]]*Append1[[#This Row],[UnitCost]]) - Finance!B21) -> 1298 | N13: =IF(K13>50000, "VIP", IF(K13>=20000, "Regular", "Low Value")) -> Low Value | O13: =INDEX(E13:E102, MATCH(H13, H13:H102, 0)) -> Headphones | P13: Accessories | Q13: 323 | R13: =_xlfn.XLOOKUP(A13, Operations!A:A, Operations!B:B, "") -> 2
A14: Q1-004 | B14: 45703.571 | C14: East | D14: 1018 | E14: Smartphone | F14: 8 | G14: 726 | H14: =_xlfn.XLOOKUP(E14, Products!A:A, Products!B:B, "Not Found") -> Electronics | I14: =_xlfn.XLOOKUP(E14, Products!A:A, Products!D:D, 0) -> 97 | J14: =_xlfn.XLOOKUP(E14, Products!A:A, Products!E:E, 0) -> 0.08 | K14: =SUM(F14*G14) -> 5808 | L14: =SUM(K14*(1-J14)) -> 5343.36 | M14: =SUM(K14- (Append1[[#This Row],[Quantity]]*Append1[[#This Row],[UnitCost]]) - Finance!B3) -> -38288 | N14: =IF(K14>50000, "VIP", IF(K14>=20000, "Regular", "Low Value")) -> Low Value | O14: =INDEX(E14:E103, MATCH(H14, H14:H103, 0)) -> Smartphone | P14: Electronics | Q14: 97 | R14: =_xlfn.XLOOKUP(A14, Operations!A:A, Operations!B:B, "") -> 4
A15: Q1-008 | B15: 45707.394 | C15: South | D15: 1014 | E15: Tablet | F15: 5 | G15: 1134 | H15: =_xlfn.XLOOKUP(E15, Products!A:A, Products!B:B, "Not Found") -> Electronics | I15: =_xlfn.XLOOKUP(E15, Products!A:A, Products!D:D, 0) -> 492 | J15: =_xlfn.XLOOKUP(E15, Products!A:A, Products!E:E, 0) -> 0.14 | K15: =SUM(F15*G15) -> 5670 | L15: =SUM(K15*(1-J15)) -> 4876.2 | M15: =SUM(K15- (Append1[[#This Row],[Quantity]]*Append1[[#This Row],[UnitCost]]) - Finance!B3) -> -40110 | N15: =IF(K15>50000, "VIP", IF(K15>=20000, "Regular", "Low Value")) -> Low Value | O15: =INDEX(E15:E104, MATCH(H15, H15:H104, 0)) -> Tablet | P15: Electronics | Q15: 492 | R15: =_xlfn.XLOOKUP(A15, Operations!A:A, Operations!B:B, "") -> 8
A16: Q1-001 | B16: 45708.027 | C16: South | D16: 1018 | E16: Tablet | F16: 1 | G16: 730 | H16: =_xlfn.XLOOKUP(E16, Products!A:A, Products!B:B, "Not Found") -> Electronics | I16: =_xlfn.XLOOKUP(E16, Products!A:A, Products!D:D, 0) -> 492 | J16: =_xlfn.XLOOKUP(E16, Products!A:A, Products!E:E, 0) -> 0.14 | K16: =SUM(F16*G16) -> 730 | L16: =SUM(K16*(1-J16)) -> 627.8 | M16: =SUM(K16- (Append1[[#This Row],[Quantity]]*Append1[[#This Row],[UnitCost]]) - Finance!B3) -> -43082 | N16: =IF(K16>50000, "VIP", IF(K16>=20000, "Regular", "Low Value")) -> Low Value | O16: =INDEX(E16:E105, MATCH(H16, H16:H105, 0)) -> Tablet | P16: Electronics | Q16: 492 | R16: =_xlfn.XLOOKUP(A16, Operations!A:A, Operations!B:B, "") -> 5
A17: Q1-025 | B17: 45710.772 | C17: South | D17: 1007 | E17: Monitor | F17: 8 | G17: 1770 | H17: =_xlfn.XLOOKUP(E17, Products!A:A, Products!B:B, "Not Found") -> Electronics | I17: =_xlfn.XLOOKUP(E17, Products!A:A, Products!D:D, 0) -> 463 | J17: =_xlfn.XLOOKUP(E17, Products!A:A, Products!E:E, 0) -> 0.23 | K17: =SUM(F17*G17) -> 14160 | L17: =SUM(K17*(1-J17)) -> 10903.2 | M17: =SUM(K17- (Append1[[#This Row],[Quantity]]*Append1[[#This Row],[UnitCost]]) - Finance!B27) -> 10456 | N17: =IF(K17>50000, "VIP", IF(K17>=20000, "Regular", "Low Value")) -> Low Value | O17: =INDEX(E17:E106, MATCH(H17, H17:H106, 0)) -> Monitor | P17: Electronics | Q17: 463 | R17: =_xlfn.XLOOKUP(A17, Operations!A:A, Operations!B:B, "") -> 9
A18: Q1-002 | B18: 45712.237 | C18: South | D18: 1004 | E18: Headphones | F18: 3 | G18: 378 | H18: =_xlfn.XLOOKUP(E18, Products!A:A, Products!B:B, "Not Found") -> Accessories | I18: =_xlfn.XLOOKUP(E18, Products!A:A, Products!D:D, 0) -> 323 | J18: =_xlfn.XLOOKUP(E18, Products!A:A, Products!E:E, 0) -> 0.1 | K18: =SUM(F18*G18) -> 1134 | L18: =SUM(K18*(1-J18)) -> 1020.6 | M18: =SUM(K18- (Append1[[#This Row],[Quantity]]*Append1[[#This Row],[UnitCost]]) - Finance!B3) -> -43155 | N18: =IF(K18>50000, "VIP", IF(K18>=20000, "Regular", "Low Value")) -> Low Value | O18: =INDEX(E18:E107, MATCH(H18, H18:H107, 0)) -> Headphones | P18: Accessories | Q18: 323 | R18: =_xlfn.XLOOKUP(A18, Operations!A:A, Operations!B:B, "") -> 2
A19: Q1-021 | B19: 45713.211 | C19: South | D19: 1008 | E19: Headphones | F19: 7 | G19: 241 | H19: =_xlfn.XLOOKUP(E19, Products!A:A, Products!B:B, "Not Found") -> Accessories | I19: =_xlfn.XLOOKUP(E19, Products!A:A, Products!D:D, 0) -> 323 | J19: =_xlfn.XLOOKUP(E19, Products!A:A, Products!E:E, 0) -> 0.1 | K19: =SUM(F19*G19) -> 1687 | L19: =SUM(K19*(1-J19)) -> 1518.3 | M19: =SUM(K19- (Append1[[#This Row],[Quantity]]*Append1[[#This Row],[UnitCost]]) - Finance!B23) -> -574 | N19: =IF(K19>50000, "VIP", IF(K19>=20000, "Regular", "Low Value")) -> Low Value | O19: =INDEX(E19:E108, MATCH(H19, H19:H108, 0)) -> Headphones | P19: Accessories | Q19: 323 | R19: =_xlfn.XLOOKUP(A19, Operations!A:A, Operations!B:B, "") -> 8
A20: Q1-024 | B20: 45715.878 | C20: East | D20: 1020 | E20: Headphones | F20: 8 | G20: 911 | H20: =_xlfn.XLOOKUP(E20, Products!A:A, Products!B:B, "Not Found") -> Accessories | I20: =_xlfn.XLOOKUP(E20, Products!A:A, Products!D:D, 0) -> 323 | J20: =_xlfn.XLOOKUP(E20, Products!A:A, Products!E:E, 0) -> 0.1 | K20: =SUM(F20*G20) -> 7288 | L20: =SUM(K20*(1-J20)) -> 6559.2 | M20: =SUM(K20- (Append1[[#This Row],[Quantity]]*Append1[[#This Row],[UnitCost]]) - Finance!B26) -> 4704 | N20: =IF(K20>50000, "VIP", IF(K20>=20000, "Regular", "Low Value")) -> Low Value | O20: =INDEX(E20:E109, MATCH(H20, H20:H109, 0)) -> Headphones | P20: Accessories | Q20: 323 | R20: =_xlfn.XLOOKUP(A20, Operations!A:A, Operations!B:B, "") -> 1
A21: Q1-006 | B21: 45716.227 | C21: East | D21: 1013 | E21: Laptop | F21: 8 | G21: 1817 | H21: =_xlfn.XLOOKUP(E21, Products!A:A, Products!B:B, "Not Found") -> Electronics | I21: =_xlfn.XLOOKUP(E21, Products!A:A, Products!D:D, 0) -> 469 | J21: =_xlfn.XLOOKUP(E21, Products!A:A, Products!E:E, 0) -> 0.22 | K21: =SUM(F21*G21) -> 14536 | L21: =SUM(K21*(1-J21)) -> 11338.08 | M21: =SUM(K21- (Append1[[#This Row],[Quantity]]*Append1[[#This Row],[UnitCost]]) - Finance!B7) -> -9295 | N21: =IF(K21>50000, "VIP", IF(K21>=20000, "Regular", "Low Value")) -> Low Value | O21: =INDEX(E21:E110, MATCH(H21, H21:H110, 0)) -> Laptop | P21: Electronics | Q21: 469 | R21: =_xlfn.XLOOKUP(A21, Operations!A:A, Operations!B:B, "") -> 5
A22: Q1-014 | B22: 45717.254 | C22: South | D22: 1005 | E22: Printer | F22: 2 | G22: 505 | H22: =_xlfn.XLOOKUP(E22, Products!A:A, Products!B:B, "Not Found") -> Office | I22: =_xlfn.XLOOKUP(E22, Products!A:A, Products!D:D, 0) -> 136 | J22: =_xlfn.XLOOKUP(E22, Products!A:A, Products!E:E, 0) -> 0.1 | K22: =SUM(F22*G22) -> 1010 | L22: =SUM(K22*(1-J22)) -> 909 | M22: =SUM(K22- (Append1[[#This Row],[Quantity]]*Append1[[#This Row],[UnitCost]]) - Finance!B16) -> 738 | N22: =IF(K22>50000, "VIP", IF(K22>=20000, "Regular", "Low Value")) -> Low Value | O22: =INDEX(E22:E111, MATCH(H22, H22:H111, 0)) -> Printer | P22: Office | Q22: 136 | R22: =_xlfn.XLOOKUP(A22, Operations!A:A, Operations!B:B, "") -> 3
A23: Q1-027 | B23: 45718.188 | C23: East | D23: 1001 | E23: Monitor | F23: 7 | G23: 796 | H23: =_xlfn.XLOOKUP(E23, Products!A:A, Products!B:B, "Not Found") -> Electronics | I23: =_xlfn.XLOOKUP(E23, Products!A:A, Products!D:D, 0) -> 463 | J23: =_xlfn.XLOOKUP(E23, Products!A:A, Products!E:E, 0) -> 0.23 | K23: =SUM(F23*G23) -> 5572 | L23: =SUM(K23*(1-J23)) -> 4290.44 | M23: =SUM(K23- (Append1[[#This Row],[Quantity]]*Append1[[#This Row],[UnitCost]]) - Finance!B29) -> 2331 | N23: =IF(K23>50000, "VIP", IF(K23>=20000, "Regular", "Low Value")) -> Low Value | O23: =INDEX(E23:E112, MATCH(H23, H23:H112, 0)) -> Monitor | P23: Electronics | Q23: 463 | R23: =_xlfn.XLOOKUP(A23, Operations!A:A, Operations!B:B, "") -> 6
A24: Q1-018 | B24: 45718.933 | C24: South | D24: 1009 | E24: Monitor | F24: 7 | G24: 1149 | H24: =_xlfn.XLOOKUP(E24, Products!A:A, Products!B:B, "Not Found") -> Electronics | I24: =_xlfn.XLOOKUP(E24, Products!A:A, Products!D:D, 0) -> 463 | J24: =_xlfn.XLOOKUP(E24, Products!A:A, Products!E:E, 0) -> 0.23 | K24: =SUM(F24*G24) -> 8043 | L24: =SUM(K24*(1-J24)) -> 6193.11 | M24: =SUM(K24- (Append1[[#This Row],[Quantity]]*Append1[[#This Row],[UnitCost]]) - Finance!B20) -> 4802 | N24: =IF(K24>50000, "VIP", IF(K24>=20000, "Regular", "Low Value")) -> Low Value | O24: =INDEX(E24:E113, MATCH(H24, H24:H113, 0)) -> Monitor | P24: Electronics | Q24: 463 | R24: =_xlfn.XLOOKUP(A24, Operations!A:A, Operations!B:B, "") -> 9
A25: Q1-029 | B25: 45722.085 | C25: West | D25: 1011 | E25: Printer | F25: 2 | G25: 1660 | H25: =_xlfn.XLOOKUP(E25, Products!A:A, Products!B:B, "Not Found") -> Office | I25: =_xlfn.XLOOKUP(E25, Products!A:A, Products!D:D, 0) -> 136 | J25: =_xlfn.XLOOKUP(E25, Products!A:A, Products!E:E, 0) -> 0.1 | K25: =SUM(F25*G25) -> 3320 | L25: =SUM(K25*(1-J25)) -> 2988 | M25: =SUM(K25- (Append1[[#This Row],[Quantity]]*Append1[[#This Row],[UnitCost]]) - Finance!B31) -> 3048 | N25: =IF(K25>50000, "VIP", IF(K25>=20000, "Regular", "Low Value")) -> Low Value | O25: =INDEX(E25:E114, MATCH(H25, H25:H114, 0)) -> Printer | P25: Office | Q25: 136 | R25: =_xlfn.XLOOKUP(A25, Operations!A:A, Operations!B:B, "") -> 9
A26: Q1-022 | B26: 45723.978 | C26: West | D26: 1005 | E26: Printer | F26: 7 | G26: 1336 | H26: =_xlfn.XLOOKUP(E26, Products!A:A, Products!B:B, "Not Found") -> Office | I26: =_xlfn.XLOOKUP(E26, Products!A:A, Products!D:D, 0) -> 136 | J26: =_xlfn.XLOOKUP(E26, Products!A:A, Products!E:E, 0) -> 0.1 | K26: =SUM(F26*G26) -> 9352 | L26: =SUM(K26*(1-J26)) -> 8416.8 | M26: =SUM(K26- (Append1[[#This Row],[Quantity]]*Append1[[#This Row],[UnitCost]]) - Finance!B24) -> 8400 | N26: =IF(K26>50000, "VIP", IF(K26>=20000, "Regular", "Low Value")) -> Low Value | O26: =INDEX(E26:E115, MATCH(H26, H26:H115, 0)) -> Printer | P26: Office | Q26: 136 | R26: =_xlfn.XLOOKUP(A26, Operations!A:A, Operations!B:B, "") -> 7
A27: Q1-007 | B27: 45735.116 | C27: South | D27: 1017 | E27: Tablet | F27: 9 | G27: 1976 | H27: =_xlfn.XLOOKUP(E27, Products!A:A, Products!B:B, "Not Found") -> Electronics | I27: =_xlfn.XLOOKUP(E27, Products!A:A, Products!D:D, 0) -> 492 | J27: =_xlfn.XLOOKUP(E27, Products!A:A, Products!E:E, 0) -> 0.14 | K27: =SUM(F27*G27) -> 17784 | L27: =SUM(K27*(1-J27)) -> 15294.24 | M27: =SUM(K27- (Append1[[#This Row],[Quantity]]*Append1[[#This Row],[UnitCost]]) - Finance!B4) -> -20791 | N27: =IF(K27>50000, "VIP", IF(K27>=20000, "Regular", "Low Value")) -> Low Value | O27: =INDEX(E27:E116, MATCH(H27, H27:H116, 0)) -> Tablet | P27: Electronics | Q27: 492 | R27: =_xlfn.XLOOKUP(A27, Operations!A:A, Operations!B:B, "") -> 4
A28: Q1-003 | B28: 45736.268 | C28: West | D28: 1005 | E28: Monitor | F28: 1 | G28: 585 | H28: =_xlfn.XLOOKUP(E28, Products!A:A, Products!B:B, "Not Found") -> Electronics | I28: =_xlfn.XLOOKUP(E28, Products!A:A, Products!D:D, 0) -> 463 | J28: =_xlfn.XLOOKUP(E28, Products!A:A, Products!E:E, 0) -> 0.23 | K28: =SUM(F28*G28) -> 585 | L28: =SUM(K28*(1-J28)) -> 450.45 | M28: =SUM(K28- (Append1[[#This Row],[Quantity]]*Append1[[#This Row],[UnitCost]]) - Finance!B4) -> -34025 | N28: =IF(K28>50000, "VIP", IF(K28>=20000, "Regular", "Low Value")) -> Low Value | O28: =INDEX(E28:E117, MATCH(H28, H28:H117, 0)) -> Monitor | P28: Electronics | Q28: 463 | R28: =_xlfn.XLOOKUP(A28, Operations!A:A, Operations!B:B, "") -> 6
A29: Q1-020 | B29: 45738.817 | C29: North | D29: 1004 | E29: Printer | F29: 3 | G29: 1010 | H29: =_xlfn.XLOOKUP(E29, Products!A:A, Products!B:B, "Not Found") -> Office | I29: =_xlfn.XLOOKUP(E29, Products!A:A, Products!D:D, 0) -> 136 | J29: =_xlfn.XLOOKUP(E29, Products!A:A, Products!E:E, 0) -> 0.1 | K29: =SUM(F29*G29) -> 3030 | L29: =SUM(K29*(1-J29)) -> 2727 | M29: =SUM(K29- (Append1[[#This Row],[Quantity]]*Append1[[#This Row],[UnitCost]]) - Finance!B22) -> 2622 | N29: =IF(K29>50000, "VIP", IF(K29>=20000, "Regular", "Low Value")) -> Low Value | O29: =INDEX(E29:E118, MATCH(H29, H29:H118, 0)) -> Printer | P29: Office | Q29: 136 | R29: =_xlfn.XLOOKUP(A29, Operations!A:A, Operations!B:B, "") -> 1
A30: Q1-016 | B30: 45742.873 | C30: North | D30: 1003 | E30: Printer | F30: 8 | G30: 1220 | H30: =_xlfn.XLOOKUP(E30, Products!A:A, Products!B:B, "Not Found") -> Office | I30: =_xlfn.XLOOKUP(E30, Products!A:A, Products!D:D, 0) -> 136 | J30: =_xlfn.XLOOKUP(E30, Products!A:A, Products!E:E, 0) -> 0.1 | K30: =SUM(F30*G30) -> 9760 | L30: =SUM(K30*(1-J30)) -> 8784 | M30: =SUM(K30- (Append1[[#This Row],[Quantity]]*Append1[[#This Row],[UnitCost]]) - Finance!B18) -> 8672 | N30: =IF(K30>50000, "VIP", IF(K30>=20000, "Regular", "Low Value")) -> Low Value | O30: =INDEX(E30:E119, MATCH(H30, H30:H119, 0)) -> Printer | P30: Office | Q30: 136 | R30: =_xlfn.XLOOKUP(A30, Operations!A:A, Operations!B:B, "") -> 3
A31: Q1-010 | B31: 45743.202 | C31: West | D31: 1010 | E31: Headphones | F31: 2 | G31: 283 | H31: =_xlfn.XLOOKUP(E31, Products!A:A, Products!B:B, "Not Found") -> Accessories | I31: =_xlfn.XLOOKUP(E31, Products!A:A, Products!D:D, 0) -> 323 | J31: =_xlfn.XLOOKUP(E31, Products!A:A, Products!E:E, 0) -> 0.1 | K31: =SUM(F31*G31) -> 566 | L31: =SUM(K31*(1-J31)) -> 509.4 | M31: =SUM(K31- (Append1[[#This Row],[Quantity]]*Append1[[#This Row],[UnitCost]]) - Finance!B12) -> -80 | N31: =IF(K31>50000, "VIP", IF(K31>=20000, "Regular", "Low Value")) -> Low Value | O31: =INDEX(E31:E120, MATCH(H31, H31:H120, 0)) -> Headphones | P31: Accessories | Q31: 323 | R31: =_xlfn.XLOOKUP(A31, Operations!A:A, Operations!B:B, "") -> 2
A32: Q2-019 | B32: 45749.993 | C32: North | D32: 1010 | E32: Printer | F32: 1 | G32: 648 | H32: =_xlfn.XLOOKUP(E32, Products!A:A, Products!B:B, "Not Found") -> Office | I32: =_xlfn.XLOOKUP(E32, Products!A:A, Products!D:D, 0) -> 136 | J32: =_xlfn.XLOOKUP(E32, Products!A:A, Products!E:E, 0) -> 0.1 | K32: =SUM(F32*G32) -> 648 | L32: =SUM(K32*(1-J32)) -> 583.2 | M32: =SUM(K32- (Append1[[#This Row],[Quantity]]*Append1[[#This Row],[UnitCost]]) - Finance!B51) -> 512 | N32: =IF(K32>50000, "VIP", IF(K32>=20000, "Regular", "Low Value")) -> Low Value | O32: =INDEX(E32:E121, MATCH(H32, H32:H121, 0)) -> Printer | P32: Office | Q32: 136 | R32: =_xlfn.XLOOKUP(A32, Operations!A:A, Operations!B:B, "") -> 8
A33: Q2-030 | B33: 45752.783 | C33: East | D33: 1006 | E33: Headphones | F33: 2 | G33: 1035 | H33: =_xlfn.XLOOKUP(E33, Products!A:A, Products!B:B, "Not Found") -> Accessories | I33: =_xlfn.XLOOKUP(E33, Products!A:A, Products!D:D, 0) -> 323 | J33: =_xlfn.XLOOKUP(E33, Products!A:A, Products!E:E, 0) -> 0.1 | K33: =SUM(F33*G33) -> 2070 | L33: =SUM(K33*(1-J33)) -> 1863 | M33: =SUM(K33- (Append1[[#This Row],[Quantity]]*Append1[[#This Row],[UnitCost]]) - Finance!B62) -> 1424 | N33: =IF(K33>50000, "VIP", IF(K33>=20000, "Regular", "Low Value")) -> Low Value | O33: =INDEX(E33:E122, MATCH(H33, H33:H122, 0)) -> Headphones | P33: Accessories | Q33: 323 | R33: =_xlfn.XLOOKUP(A33, Operations!A:A, Operations!B:B, "") -> 8
A34: Q2-011 | B34: 45754.452 | C34: South | D34: 1012 | E34: Headphones | F34: 3 | G34: 1781 | H34: =_xlfn.XLOOKUP(E34, Products!A:A, Products!B:B, "Not Found") -> Accessories | I34: =_xlfn.XLOOKUP(E34, Products!A:A, Products!D:D, 0) -> 323 | J34: =_xlfn.XLOOKUP(E34, Products!A:A, Products!E:E, 0) -> 0.1 | K34: =SUM(F34*G34) -> 5343 | L34: =SUM(K34*(1-J34)) -> 4808.7 | M34: =SUM(K34- (Append1[[#This Row],[Quantity]]*Append1[[#This Row],[UnitCost]]) - Finance!B43) -> 4374 | N34: =IF(K34>50000, "VIP", IF(K34>=20000, "Regular", "Low Value")) -> Low Value | O34: =INDEX(E34:E123, MATCH(H34, H34:H123, 0)) -> Headphones | P34: Accessories | Q34: 323 | R34: =_xlfn.XLOOKUP(A34, Operations!A:A, Operations!B:B, "") -> 5
A35: Q2-014 | B35: 45754.48 | C35: North | D35: 1009 | E35: Laptop | F35: 8 | G35: 1539 | H35: =_xlfn.XLOOKUP(E35, Products!A:A, Products!B:B, "Not Found") -> Electronics | I35: =_xlfn.XLOOKUP(E35, Products!A:A, Products!D:D, 0) -> 469 | J35: =_xlfn.XLOOKUP(E35, Products!A:A, Products!E:E, 0) -> 0.22 | K35: =SUM(F35*G35) -> 12312 | L35: =SUM(K35*(1-J35)) -> 9603.36 | M35: =SUM(K35- (Append1[[#This Row],[Quantity]]*Append1[[#This Row],[UnitCost]]) - Finance!B46) -> 8560 | N35: =IF(K35>50000, "VIP", IF(K35>=20000, "Regular", "Low Value")) -> Low Value | O35: =INDEX(E35:E124, MATCH(H35, H35:H124, 0)) -> Laptop | P35: Electronics | Q35: 469 | R35: =_xlfn.XLOOKUP(A35, Operations!A:A, Operations!B:B, "") -> 4
A36: Q2-026 | B36: 45756.893 | C36: East | D36: 1005 | E36: Printer | F36: 2 | G36: 109 | H36: =_xlfn.XLOOKUP(E36, Products!A:A, Products!B:B, "Not Found") -> Office | I36: =_xlfn.XLOOKUP(E36, Products!A:A, Products!D:D, 0) -> 136 | J36: =_xlfn.XLOOKUP(E36, Products!A:A, Products!E:E, 0) -> 0.1 | K36: =SUM(F36*G36) -> 218 | L36: =SUM(K36*(1-J36)) -> 196.2 | M36: =SUM(K36- (Append1[[#This Row],[Quantity]]*Append1[[#This Row],[UnitCost]]) - Finance!B58) -> -54 | N36: =IF(K36>50000, "VIP", IF(K36>=20000, "Regular", "Low Value")) -> Low Value | O36: =INDEX(E36:E125, MATCH(H36, H36:H125, 0)) -> Printer | P36: Office | Q36: 136 | R36: =_xlfn.XLOOKUP(A36, Operations!A:A, Operations!B:B, "") -> 2
A37: Q2-009 | B37: 45759.132 | C37: West | D37: 1020 | E37: Laptop | F37: 8 | G37: 1331 | H37: =_xlfn.XLOOKUP(E37, Products!A:A, Products!B:B, "Not Found") -> Electronics | I37: =_xlfn.XLOOKUP(E37, Products!A:A, Products!D:D, 0) -> 469 | J37: =_xlfn.XLOOKUP(E37, Products!A:A, Products!E:E, 0) -> 0.22 | K37: =SUM(F37*G37) -> 10648 | L37: =SUM(K37*(1-J37)) -> 8305.44 | M37: =SUM(K37- (Append1[[#This Row],[Quantity]]*Append1[[#This Row],[UnitCost]]) - Finance!B41) -> 6896 | N37: =IF(K37>50000, "VIP", IF(K37>=20000, "Regular", "Low Value")) -> Low Value | O37: =INDEX(E37:E126, MATCH(H37, H37:H126, 0)) -> Laptop | P37: Electronics | Q37: 469 | R37: =_xlfn.XLOOKUP(A37, Operations!A:A, Operations!B:B, "") -> 7
A38: Q2-010 | B38: 45760.76 | C38: West | D38: 1001 | E38: Smartphone | F38: 2 | G38: 222 | H38: =_xlfn.XLOOKUP(E38, Products!A:A, Products!B:B, "Not Found") -> Electronics | I38: =_xlfn.XLOOKUP(E38, Products!A:A, Products!D:D, 0) -> 97 | J38: =_xlfn.XLOOKUP(E38, Products!A:A, Products!E:E, 0) -> 0.08 | K38: =SUM(F38*G38) -> 444 | L38: =SUM(K38*(1-J38)) -> 408.48 | M38: =SUM(K38- (Append1[[#This Row],[Quantity]]*Append1[[#This Row],[UnitCost]]) - Finance!B42) -> 250 | N38: =IF(K38>50000, "VIP", IF(K38>=20000, "Regular", "Low Value")) -> Low Value | O38: =INDEX(E38:E127, MATCH(H38, H38:H127, 0)) -> Smartphone | P38: Electronics | Q38: 97 | R38: =_xlfn.XLOOKUP(A38, Operations!A:A, Operations!B:B, "") -> 4
A39: Q2-007 | B39: 45766.596 | C39: East | D39: 1010 | E39: Printer | F39: 5 | G39: 1485 | H39: =_xlfn.XLOOKUP(E39, Products!A:A, Products!B:B, "Not Found") -> Office | I39: =_xlfn.XLOOKUP(E39, Products!A:A, Products!D:D, 0) -> 136 | J39: =_xlfn.XLOOKUP(E39, Products!A:A, Products!E:E, 0) -> 0.1 | K39: =SUM(F39*G39) -> 7425 | L39: =SUM(K39*(1-J39)) -> 6682.5 | M39: =SUM(K39- (Append1[[#This Row],[Quantity]]*Append1[[#This Row],[UnitCost]]) - Finance!B39) -> 6745 | N39: =IF(K39>50000, "VIP", IF(K39>=20000, "Regular", "Low Value")) -> Low Value | O39: =INDEX(E39:E128, MATCH(H39, H39:H128, 0)) -> Printer | P39: Office | Q39: 136 | R39: =_xlfn.XLOOKUP(A39, Operations!A:A, Operations!B:B, "") -> 1
A40: Q2-008 | B40: 45770.167 | C40: East | D40: 1015 | E40: Smartphone | F40: 3 | G40: 1472 | H40: =_xlfn.XLOOKUP(E40, Products!A:A, Products!B:B, "Not Found") -> Electronics | I40: =_xlfn.XLOOKUP(E40, Products!A:A, Products!D:D, 0) -> 97 | J40: =_xlfn.XLOOKUP(E40, Products!A:A, Products!E:E, 0) -> 0.08 | K40: =SUM(F40*G40) -> 4416 | L40: =SUM(K40*(1-J40)) -> 4062.72 | M40: =SUM(K40- (Append1[[#This Row],[Quantity]]*Append1[[#This Row],[UnitCost]]) - Finance!B40) -> 4125 | N40: =IF(K40>50000, "VIP", IF(K40>=20000, "Regular", "Low Value")) -> Low Value | O40: =INDEX(E40:E129, MATCH(H40, H40:H129, 0)) -> Smartphone | P40: Electronics | Q40: 97 | R40: =_xlfn.XLOOKUP(A40, Operations!A:A, Operations!B:B, "") -> 4
...

Sheet Dashboard
A1: TotalRevenue | B1: TotalProfit | C1: TopCustomer
A2: =SUM(Append1[Discounted Revenue]) -> 370395.88 | B2: =SUM(Append1[Profit]) -> -192490 | C2: =INDEX(Sales_All!D2:D91, MATCH(MAX(Sales_All!L2:L91), Sales_All!L2:L91, 0)) -> 1017
A4: Count of Product | B4: Column Labels
A5: Row Labels | B5: East | C5: North | D5: South | E5: West | F5: Grand Total
A6: Accessories | B6: 6 | C6: 4 | D6: 4 | E6: 3 | F6: 17
A7: Electronics | B7: 11 | C7: 13 | D7: 15 | E7: 19 | F7: 58
A8: Office | B8: 4 | C8: 5 | D8: 4 | E8: 2 | F8: 15
A9: Grand Total | B9: 21 | C9: 22 | D9: 23 | E9: 24 | F9: 90

Sheet Customers
A1: CustomerID | B1: FirstName | C1: LastName | D1: Email | E1: Region | F1: Standardized | G1: Extracted First Name | H1: Extracted Last Name | I1: Extracted Email
A2: 1001 | B2: Naledi | C2: Pillay | D2: naledi.pillay@example.com | E2: East | F2: Naledi Pillay | G2: Naledi | H2: Pillay | I2: example.com
A3: 1002 | B3: Michael | C3: van Wyk | D3: michael.van wyk@example.com | E3: East | F3: Michael Van Wyk | G3: Michael | H3: van | I3: example.com
A4: 1003 | B4: Naledi | C4: Botha | D4: naledi.botha@example.com | E4: East | F4: Naledi Botha | G4: Naledi | H4: Botha | I4: example.com
A5: 1004 | B5: Naledi | C5: Botha | D5: naledi.botha@example.com | E5: North | F5: Naledi Botha | G5: Naledi | H5: Botha | I5: example.com
A6: 1005 | B6: Michael | C6: Johnson | D6: michael.johnson@example.com | E6: North | F6: Michael Johnson | G6: Michael | H6: Johnson | I6: example.com
A7: 1006 | B7: Emily | C7: Johnson | D7: emily.johnson@example.com | E7: South | F7: Emily Johnson | G7: Emily | H7: Johnson | I7: example.com
A8: 1007 | B8: Michael | C8: Nguyen | D8: michael.nguyen@example.com | E8: West | F8: Michael Nguyen | G8: Michael | H8: Nguyen | I8: example.com
A9: 1008 | B9: Sipho | C9: Johnson | D9: sipho.johnson@example.com | E9: East | F9: Sipho Johnson | G9: Sipho | H9: Johnson | I9: example.com
A10: 1009 | B10: Sarah | C10: Nguyen | D10: sarah.nguyen@example.com | E10: North | F10: Sarah Nguyen | G10: Sarah | H10: Nguyen | I10: example.com
A11: 1010 | B11: John | C11: Brown | D11: john.brown@example.com | E11: East | F11: John Brown | G11: John | H11: Brown | I11: example.com
A12: 1011 | B12: John | C12: Smith | D12: john.smith@example.com | E12: South | F12: John Smith | G12: John | H12: Smith | I12: example.com
A13: 1012 | B13: Naledi | C13: van Wyk | D13: naledi.van wyk@example.com | E13: East | F13: Naledi Van Wyk | G13: Naledi | H13: van | I13: example.com
... A29: 1018 | B29: Michael | C29: Mlambo | D29: michael.mlambo@example.com | E29: South | F29: Michael Mlambo | G29: Michael | H29: Mlambo | I29: example.com

Sheet Products
A1: Product | B1: Category | C1: UnitPrice | D1: UnitCost | E1: Discount
A2: Laptop | B2: Electronics | C2: 1299 | D2: 469 | E2: 0.22
A3: Tablet | B3: Electronics | C3: 1613 | D3: 492 | E3: 0.14
A4: Smartphone | B4: Electronics | C4: 1402 | D4: 97 | E4: 0.08
A5: Headphones | B5: Accessories | C5: 106 | D5: 323 | E5: 0.1
A6: Monitor | B6: Electronics | C6: 396 | D6: 463 | E6: 0.23
A7: Printer | B7: Office | C7: 1635 | D7: 136 | E7: 0.1
A9: DYNAMIC RANGE
A10: {=OFFSET($A$2,0,0,COUNTA($A:$A)-1,2)} -> Laptop | B10: Electronics
A11: Tablet | B11: Electronics
A12: Smartphone | B12: Electronics
A13: Headphones | B13: Accessories
A14: Monitor | B14: Electronics
A15: Printer | B15: Office
A16: 0 | B16: 0

Sheet Operations
A1: OrderID | B1: DeliveryDays | C1: ReturnRate | D1: Operational Efficiency
A2: Q1-001 | B2: 5 | C2: 0.01 | D2: =IF(AND(B2<=3,C2<=0.05),"Efficient", "Needs Attention") -> Needs Attention
A3: Q1-002 | B3: 2 | C3: 0.03 | D3: =IF(AND(B3<=3,C3<=0.05),"Efficient", "Needs Attention") -> Efficient
A4: Q1-003 | B4: 6 | C4: 0.05 | D4: =IF(AND(B4<=3,C4<=0.05),"Efficient", "Needs Attention") -> Needs Attention
A5: Q1-004 | B5: 4 | C5: 0.07 | D5: =IF(AND(B5<=3,C5<=0.05),"Efficient", "Needs Attention") -> Needs Attention
A6: Q1-005 | B6: 5 | C6: 0.03 | D6: =IF(AND(B6<=3,C6<=0.05),"Efficient", "Needs Attention") -> Needs Attention
A7: Q1-006 | B7: 5 | C7: 0.06 | D7: =IF(AND(B7<=3,C7<=0.05),"Efficient", "Needs Attention") -> Needs Attention
A8: Q1-007 | B8: 4 | C8: 0.02 | D8: =IF(AND(B8<=3,C8<=0.05),"Efficient", "Needs Attention") -> Needs Attention
A9: Q1-008 | B9: 8 | C9: 0.07 | D9: =IF(AND(B9<=3,C9<=0.05),"Efficient", "Needs Attention") -> Needs Attention
A10: Q1-009 | B10: 2 | C10: 0.08 | D10: =IF(AND(B10<=3,C10<=0.05),"Efficient", "Needs Attention") -> Needs Attention
A11: Q1-010 | B11: 2 | C11: 0.08 | D11: =IF(AND(B11<=3,C11<=0.05),"Efficient", "Needs Attention") -> Needs Attention
A12: Q1-011 | B12: 8 | C12: 0.06 | D12: =IF(AND(B12<=3,C12<=0.05),"Efficient", "Needs Attention") -> Needs Attention
A13: Q1-012 | B13: 8 | C13: 0.03 | D13: =IF(AND(B13<=3,C13<=0.05),"Efficient", "Needs Attention") -> Needs Attention
... A91: Q3-030 | B91: 5 | C91: 0.09 | D91: =IF(AND(B91<=3,C91<=0.05),"Efficient", "Needs Attention") -> Needs Attention

Sheet Finance
A1: Month | B1: Overheads | C1: Salaries | D1: OtherExpenses | E1: NetProfit
A2: 45688 | B2: 25640 | C2: 60082 | D2: 21492 | E2: =SUM(B2:C2) -> 85722
A3: 45716 | B3: 43320 | C3: 70533 | D3: 27724 | E3: =SUM(B3:C3) -> 113853
A4: 45747 | B4: 34147 | C4: 63890 | D4: 17738 | E4: =SUM(B4:C4) -> 98037
A5: 45777 | B5: 44423 | C5: 90674 | D5: 21152 | E5: =SUM(B5:C5) -> 135097
A6: 45808 | B6: 32119 | C6: 55646 | D6: 19723 | E6: =SUM(B6:C6) -> 87765
A7: 45838 | B7: 20079 | C7: 99954 | D7: 15769 | E7: =SUM(B7:C7) -> 120033
A8: 45869 | B8: 36304 | C8: 63297 | D8: 25453 | E8: =SUM(B8:C8) -> 99601
A9: 45900 | B9: 36734 | C9: 93760 | D9: 16230 | E9: =SUM(B9:C9) -> 130494
A10: 45930 | B10: 34260 | C10: 70760 | D10: 28818 | E10: =SUM(B10:C10) -> 105020

Sheet Sales_Q1
A1: OrderID | B1: Date | C1: Region | D1: CustomerID | E1: Product | F1: Quantity | G1: UnitPrice
A2: Q1-001 | B2: 45708.027 | C2: South | D2: 1018 | E2: Tablet | F2: 1 | G2: 730
A3: Q1-002 | B3: 45712.237 | C3: South | D3: 1004 | E3: Headphones | F3: 3 | G3: 378
A4: Q1-003 | B4: 45736.268 | C4: West | D4: 1005 | E4: Monitor | F4: 1 | G4: 585
A5: Q1-004 | B5: 45703.571 | C5: East | D5: 1018 | E5: Smartphone | F5: 8 | G5: 726
A6: Q1-005 | B6: 45663.686 | C6: North | D6: 1012 | E6: Laptop | F6: 2 | G6: 709
A7: Q1-006 | B7: 45716.227 | C7: East | D7: 1013 | E7: Laptop | F7: 8 | G7: 1817
A8: Q1-007 | B8: 45735.116 | C8: South | D8: 1017 | E8: Tablet | F8: 9 | G8: 1976
A9: Q1-008 | B9: 45707.394 | C9: South | D9: 1014 | E9: Tablet | F9: 5 | G9: 1134
A10: Q1-009 | B10: 45671.497 | C10: South | D10: 1020 | E10: Printer | F10: 1 | G10: 1220
A11: Q1-010 | B11: 45743.202 | C11: West | D11: 1010 | E11: Headphones | F11: 2 | G11: 283
A12: Q1-011 | B12: 45684.929 | C12: West | D12: 1019 | E12: Laptop | F12: 9 | G12: 417
A13: Q1-012 | B13: 45662.79 | C13: South | D13: 1016 | E13: Laptop | F13: 3 | G13: 1692
... A31: Q1-030 | B31: 45666.628 | C31: East | D31: 1016 | E31: Monitor | F31: 5 | G31: 1119

Sheet Sales_Q2
A1: OrderID | B1: Date | C1: Region | D1: CustomerID | E1: Product | F1: Quantity | G1: UnitPrice
A2: Q2-001 | B2: 45770.272 | C2: North | D2: 1016 | E2: Tablet | F2: 7 | G2: 1039
A3: Q2-002 | B3: 45821.985 | C3: West | D3: 1010 | E3: Smartphone | F3: 2 | G3: 809
A4: Q2-003 | B4: 45774.625 | C4: West | D4: 1014 | E4: Monitor | F4: 5 | G4: 1951
A5: Q2-004 | B5: 45789.476 | C5: South | D5: 1009 | E5: Smartphone | F5: 1 | G5: 1187
A6: Q2-005 | B6: 45771.115 | C6: North | D6: 1018 | E6: Headphones | F6: 9 | G6: 1259
A7: Q2-006 | B7: 45833.931 | C7: North | D7: 1010 | E7: Monitor | F7: 6 | G7: 1460
A8: Q2-007 | B8: 45766.596 | C8: East | D8: 1010 | E8: Printer | F8: 5 | G8: 1485
A9: Q2-008 | B9: 45770.167 | C9: East | D9: 1015 | E9: Smartphone | F9: 3 | G9: 1472
A10: Q2-009 | B10: 45759.132 | C10: West | D10: 1020 | E10: Laptop | F10: 8 | G10: 1331
A11: Q2-010 | B11: 45760.76 | C11: West | D11: 1001 | E11: Smartphone | F11: 2 | G11: 222
A12: Q2-011 | B12: 45754.452 | C12: South | D12: 1012 | E12: Headphones | F12: 3 | G12: 1781
A13: Q2-012 | B13: 45823.74 | C13: West | D13: 1001 | E13: Headphones | F13: 2 | G13: 1545
... A31: Q2-030 | B31: 45752.783 | C31: East | D31: 1006 | E31: Headphones | F31: 2 | G31: 1035

Sheet Sales_Q3
A1: OrderID | B1: Date | C1: Region | D1: CustomerID | E1: Product | F1: Quantity | G1: UnitPrice
A2: Q3-001 | B2: 45839.828 | C2: North | D2: 1001 | E2: Monitor | F2: 4 | G2: 160
A3: Q3-002 | B3: 45859.5 | C3: South | D3: 1001 | E3: Monitor | F3: 1 | G3: 233
A4: Q3-003 | B4: 45894.505 | C4: West | D4: 1010 | E4: Smartphone | F4: 9 | G4: 312
A5: Q3-004 | B5: 45844.234 | C5: East | D5: 1019 | E5: Laptop | F5: 3 | G5: 603
A6: Q3-005 | B6: 45850.673 | C6: South | D6: 1006 | E6: Monitor | F6: 8 | G6: 1987
A7: Q3-006 | B7: 45891.791 | C7: North | D7: 1008 | E7: Laptop | F7: 3 | G7: 589
A8: Q3-007 | B8: 45886.322 | C8: East | D8: 1006 | E8: Headphones | F8: 2 | G8: 1742
A9: Q3-008 | B9: 45857.335 | C9: South | D9: 1015 | E9: Smartphone | F9: 4 | G9: 1461
A10: Q3-009 | B10: 45914.314 | C10: South | D10: 1002 | E10: Laptop | F10: 3 | G10: 1133
A11: Q3-010 | B11: 45926.582 | C11: East | D11: 1018 | E11: Monitor | F11: 5 | G11: 644
A12: Q3-011 | B12: 45897.155 | C12: North | D12: 1002 | E12: Headphones | F12: 2 | G12: 1265
A13: Q3-012 | B13: 45868.096 | C13: West | D13: 1011 | E13: Tablet | F13: 3 | G13: 1634
... A31: Q3-030 | B31: 45898.259 | C31: West | D31: 1003 | E31: Monitor | F31: 3 | G31: 651
